<?xml version="1.0"?>
<robot xmlns:xacro="http://www.ros.org/wiki/xacro">

  <material name="gray">
    <color rgba="0.8 0.8 0.8 1"/>
  </material>
 
  <material name="white">
    <color rgba="1 1 1 1"/>
  </material>

  <!--For now, set the inertial values according to here https://github.com/waveshareteam/roarm_ws_em0-->
  <!--The current values are for the gripper layout roarm m2-->

  <link name="base_link">
    <visual>
      <geometry>
        <mesh filename="package://roarm/meshes/base.stl"/>
      </geometry>
      <origin rpy="0 0 0" xyz="0 0 0"/>
      <material name="gray"/>
    </visual>
    <collision>
      <geometry>
        <mesh filename="package://roarm/meshes/base.stl"/>
      </geometry>
      <origin rpy="0 0 0" xyz="0 0 0"/>
    </collision>
    <inertial>
      <origin
        xyz="0.00373847392098165 -1.52445893424664E-10 0.0264265327292804"
        rpy="0 0 0" />
      <mass
        value="0.326392759093976" />
      <inertia
        ixx="0.000224202818963409"
        ixy="-1.96773409840189E-13"
        ixz="-2.99224798427881E-05"
        iyy="0.000286616921839535"
        iyz="-3.10964171549742E-13"
        izz="0.000349957607258242" />
    </inertial>
  </link>

  <link name="l1_link">
    <visual>
      <geometry>
        <mesh filename="package://roarm/meshes/L1.stl"/>
      </geometry>
      <origin rpy="0 0 0" xyz="0 0 0"/>
      <material name="white"/>
    </visual>
    <collision>
      <geometry>
        <mesh filename="package://roarm/meshes/L1.stl"/>
      </geometry>
      <origin rpy="0 0 0" xyz="0 0 0"/>
    </collision>
    <inertial>
      <origin
        xyz="-3.11559626639357E-12 9.70240468164796E-06 -0.0146667419724465"
        rpy="0 0 0" />
      <mass
        value="0.0928887601998397" />
      <inertia
        ixx="6.09210980255232E-05"
        ixy="-2.79207542479444E-18"
        ixz="4.24841739939559E-15"
        iyy="2.53493566630784E-05"
        iyz="2.16442830142331E-08"
        izz="4.88050835919342E-05" />
    </inertial>
  </link>

  <link name="l2_link">
    <visual>
      <geometry>
        <mesh filename="package://roarm/meshes/L2.stl"/>
      </geometry>
      <origin rpy="0 0 0" xyz="0 0 -0.03796"/>
      <material name="white"/>
    </visual>
    <collision>
      <geometry>
        <mesh filename="package://roarm/meshes/L2.stl"/>
      </geometry>
      <origin rpy="0 0 0" xyz="0 0 -0.03796"/>
    </collision>
    <inertial>
      <origin
        xyz="0.122021157535333 6.61338425981053E-05 -9.50311342843365E-05"
        rpy="0 0 0" />
      <mass
        value="0.0895817175833772" />
      <inertia
        ixx="2.6269354271334E-05"
        ixy="-2.55344668379587E-06"
        ixz="-3.90237379833709E-09"
        iyy="0.000350369536011831"
        iyz="-6.82396195680563E-09"
        izz="0.000333056833230846" />
    </inertial>
  </link>

  <link name="l3_link">
    <visual>
      <geometry>
        <mesh filename="package://roarm/meshes/L3.stl"/>
      </geometry>
      <origin rpy="0 0 0" xyz="-0.03 0 -0.27477"/>
      <material name="white"/>
    </visual>
    <collision>
      <geometry>
        <mesh filename="package://roarm/meshes/L3.stl"/>
      </geometry>
      <origin rpy="0 0 0" xyz="-0.03 0 -0.27477"/>
    </collision>
    <inertial>
      <origin
        xyz="-0.00076280945740961 -0.114419656440929 -0.000177274968057332"
        rpy="0 0 0" />
      <mass
        value="0.123009044986454" />
      <inertia
        ixx="0.000104111883333949"
        ixy="1.06443789581137E-07"
        ixz="1.54925816846055E-07"
        iyy="1.46357151076022E-05"
        iyz="-1.6435520156444E-07"
        izz="0.000104009297710106" />
    </inertial>
  </link>
 
  <link name="l4_link">
    <visual>
      <geometry>
        <mesh filename="package://roarm/meshes/L4.stl"/>
      </geometry>
      <origin rpy="0 0 0" xyz="-0.03 0 -0.49076"/>
      <material name="white"/>
    </visual>
    <collision>
      <geometry>
        <mesh filename="package://roarm/meshes/L4.stl"/>
      </geometry>
      <origin rpy="0 0 0" xyz="-0.03 0 -0.49076"/>
    </collision>
    <inertial>
      <origin
        xyz="0.0288857415118809 -0.000776842039187049 -0.000779764534254559"
        rpy="0 0 0" />
      <mass
        value="0.00365697683069397" />
      <inertia
        ixx="1.15139272656909E-06"
        ixy="1.31250385773157E-07"
        ixz="-2.41954534039415E-13"
        iyy="2.33034171341163E-06"
        iyz="4.1392257505497E-13"
        izz="1.47179863096272E-06" />
    </inertial>
  </link>

  
  
  <joint name="base_to_L1" type="revolute">
    <axis xyz="0 0 1"/>
    <limit effort="1000.0" lower="-3.14" upper="3.14" velocity="0.5"/>
    <parent link="base_link"/>
    <child link="l1_link"/>
    <origin xyz="0 0 0"/>
  </joint>

  <joint name="L1_to_L2" type="revolute">
    <axis xyz="0 1 0"/>
    <limit effort="1000.0" lower="-1.570796" upper="1.570796" velocity="0.5"/>
    <parent link="l1_link"/>
    <child link="l2_link"/>
    <origin xyz="0 0 0.03796"/>
  </joint>

  <joint name="L2_to_L3" type="revolute">
    <axis xyz="0 1 0"/>
    <limit effort="1000.0" lower="-0.78539815" upper="3.1415926" velocity="0.5"/>
    <parent link="l2_link"/>
    <child link="l3_link"/>
    <origin xyz="0.03 0 0.23682"/>
  </joint>

  <joint name="L3_to_L4" type="revolute">
    <axis xyz="0 1 0"/>
    <limit effort="1000.0" lower="-2.3561942" upper="2.3561942" velocity="0.5"/>
    <parent link="l3_link"/>
    <child link="l4_link"/>
    <origin xyz="0 0 0.21599"/>
  </joint>

</robot>
